<mujocoinclude>
  <!-- 机器人模型 - 安装在化学实验室主实验台右侧 -->
  <!-- 绕Z轴旋转180度: quat = [cos(90°), 0, 0, sin(90°)] -->
  <body name="base" pos="1.0 0 0.96" quat="0 0 0 1">
    <geom type="mesh" rgba="1 1 1 1" mesh="base_link"/>
    <body name="Link1" pos="0 0 0.084">
      <inertial pos="0.0083082 -9.0414e-07 0.066279" quat="0.998826 -0.000217649 0.0484359 -9.45615e-05" mass="1.0225" diaginertia="0.000335358 0.0002898 0.000262912" />
      <joint name="joint1" pos="0 0 0" axis="0 0 1" range="-2.967 2.967"  actuatorfrcrange="-49 49" damping="14"/>
      <geom type="mesh" rgba="1 1 1 1" mesh="Link1"/>
      <body name="Link2" pos="0 0 0.068718" quat="0.499998 0.5 -0.500002 -0.5">
        <inertial pos="1.6176e-06 0.19554 -0.0019139" quat="0.706447 0.707766 1.47574e-05 -1.23022e-05" mass="1.925" diaginertia="0.0092613 0.00908453 0.000755251" />
        <joint name="joint2" pos="0 0 0" axis="0 0 -1" range="-1.5708 1.5708" actuatorfrcrange="-49 49" damping="14"/>
        <geom type="mesh" rgba="1 1 1 1" mesh="Link2"/>
        <body name="Link3" pos="0 0.30025 0" quat="-3.67321e-06 -1 0 0">
          <inertial pos="1.8251e-05 -0.073691 0.010704" quat="0.610035 0.792374 0.000587179 -0.000287816" mass="0.73" diaginertia="0.00059318 0.000583743 0.000125677" />
          <joint name="joint3" pos="0 0 0" axis="0 0 1" range="-1.5708 1.5708" actuatorfrcrange="-49 49" damping="14"/>
          <geom type="mesh" rgba="1 1 1 1" mesh="Link3"/>
          <body name="Link4" pos="0 -0.15558 3.5e-05" quat="0.499998 0.5 -0.5 0.500002">
            <inertial pos="0.0059454 2.5068e-05 0.051809" quat="0.695353 0.127815 0.128139 0.695505" mass="0.5174" diaginertia="0.0001193 0.000106439 8.26181e-05" />
            <joint name="joint4" pos="0 0 0" axis="0 0 1" range="-2.967 2.967" actuatorfrcrange="-9 9" damping="1.5"/>
            <geom type="mesh" rgba="1 1 1 1" mesh="Link4"/>
            <body name="Link5" pos="-3.5e-05 1.5362e-05 0.064223" quat="0.707105 0.707108 0 0">
              <inertial pos="0.0095168 0.061153 1.0106e-05" quat="0.680352 0.676005 0.209332 0.190573" mass="0.7233" diaginertia="0.000161121 0.000159399 7.529e-05" />
              <joint name="joint5" pos="0 0 0" axis="1 0 0" range="-1.5708 1.5708" actuatorfrcrange="-9 9" damping="1.5"/>
              <geom type="mesh" rgba="1 1 1 1" mesh="Link5" />
              <body name="Link6" pos="-0.00047523 0.095552 0" quat="0.70707 -0.707143 0 0">
                <inertial pos="-0.0023023 0.0016027 0.010682" quat="-0.121835 0.703576 0.107936 0.691727" mass="0.0953" diaginertia="2.46295e-05 1.34438e-05 1.31437e-05" />
                <joint name="joint6" pos="0 0 0" axis="0 0 1" range="-2.967 2.967" actuatorfrcrange="-9 9" damping="1.5"/>
                <geom type="mesh" rgba="1 1 1 1" mesh="Link6" />
                <!-- RGBD相机 1: 安装在机器人末端 (Link6) -->
                <camera name="rgbd_camera_ee" pos="0 0.06 0.02" euler="0 3.1415926 0" fovy="60" mode="fixed"/>
                <!-- 导入夹爪 -->
                <include file="../robot_iq/robotiq-2f-chain.xml"/>
              </body>
            </body>
          </body>
        </body>
      </body>
    </body>
  </body>
</mujocoinclude>

