<?xml version="1.0" encoding="utf-8"?>
<robot
  name="arm620">
  <link
    name="base_link">
    <inertial>
      <origin
        xyz="-3.493E-05 1.9321E-08 0.041738"
        rpy="0 0 0" />
      <mass
        value="1.235" />
      <inertia
        ixx="0.00069305"
        ixy="-2.4629E-09"
        ixz="-7.7538E-07"
        iyy="0.00069224"
        iyz="1.1986E-09"
        izz="0.00059207" />
    </inertial>
    <visual>
      <origin
        xyz="0 0 0"
        rpy="0 0 0" />
      <geometry>
        <mesh
          filename="./base_link.STL" />
      </geometry>
      <material
        name="">
        <color
          rgba="1 1 1 1" />
      </material>
    </visual>
    <collision>
      <origin
        xyz="0 0 0"
        rpy="0 0 0" />
      <geometry>
        <mesh
          filename="./base_link.STL" />
      </geometry>
    </collision>
  </link>
  <link
    name="Link1">
    <inertial>
      <origin
        xyz="0.0083082 -9.0414E-07 0.066279"
        rpy="0 0 0" />
      <mass
        value="1.0225" />
      <inertia
        ixx="0.00033468"
        ixy="-1.0629E-08"
        ixz="-6.9769E-06"
        iyy="0.0002898"
        iyz="-1.0465E-08"
        izz="0.00026359" />
    </inertial>
    <visual>
      <origin
        xyz="0 0 0"
        rpy="0 0 0" />
      <geometry>
        <mesh
          filename="../meshes/arm620/Link1.STL" />
      </geometry>
      <material
        name="">
        <color
          rgba="1 1 1 1" />
      </material>
    </visual>
    <collision>
      <origin
        xyz="0 0 0"
        rpy="0 0 0" />
      <geometry>
        <mesh
          filename="../meshes/arm620/Link1.STL" />
      </geometry>
    </collision>
  </link>
  <joint
    name="joint1"
    type="revolute">
    <origin
      xyz="0 0 0.084"
      rpy="0 0 0" />
    <parent
      link="base_link" />
    <child
      link="Link1" />
    <axis
      xyz="0 0 1" />
    <limit
      lower="-2.967"
      upper="2.967"
      effort="0"
      velocity="0" />
  </joint>
  <link
    name="Link2">
    <inertial>
      <origin
        xyz="1.6176E-06 0.19554 -0.0019139"
        rpy="0 0 0" />
      <mass
        value="1.925" />
      <inertia
        ixx="0.0092613"
        ixy="2.9244E-08"
        ixz="-6.7107E-09"
        iyy="0.00075528"
        iyz="-1.5539E-05"
        izz="0.0090845" />
    </inertial>
    <visual>
      <origin
        xyz="0 0 0"
        rpy="0 0 0" />
      <geometry>
        <mesh
          filename="../meshes/arm620/Link2.STL" />
      </geometry>
      <material
        name="">
        <color
          rgba="1 1 1 1" />
      </material>
    </visual>
    <collision>
      <origin
        xyz="0 0 0"
        rpy="0 0 0" />
      <geometry>
        <mesh
          filename="../meshes/arm620/Link2.STL" />
      </geometry>
    </collision>
  </link>
  <joint
    name="joint2"
    type="revolute">
    <origin
      xyz="0 0 0.068718"
      rpy="1.5708 0 -1.5708" />
    <parent
      link="Link1" />
    <child
      link="Link2" />
    <axis
      xyz="0 0 -1" />
    <limit
      lower="-1.5708"
      upper="1.5708"
      effort="0"
      velocity="0" />
  </joint>
  <link
    name="Link3">
    <inertial>
      <origin
        xyz="1.8251E-05 -0.073691 0.010704"
        rpy="0 0 0" />
      <mass
        value="0.73" />
      <inertia
        ixx="0.00059318"
        ixy="1.2073E-07"
        ixz="1.9423E-08"
        iyy="0.00015563"
        iyz="-0.00011324"
        izz="0.00055379" />
    </inertial>
    <visual>
      <origin
        xyz="0 0 0"
        rpy="0 0 0" />
      <geometry>
        <mesh
          filename="../meshes/arm620/Link3.STL" />
      </geometry>
      <material
        name="">
        <color
          rgba="1 1 1 1" />
      </material>
    </visual>
    <collision>
      <origin
        xyz="0 0 0"
        rpy="0 0 0" />
      <geometry>
        <mesh
          filename="../meshes/arm620/Link3.STL" />
      </geometry>
    </collision>
  </link>
  <joint
    name="joint3"
    type="revolute">
    <origin
      xyz="0 0.30025 0"
      rpy="-3.1416 0 0" />
    <parent
      link="Link2" />
    <child
      link="Link3" />
    <axis
      xyz="0 0 1" />
    <limit
      lower="-1.5708"
      upper="1.5708"
      effort="0"
      velocity="0" />
  </joint>
  <link
    name="Link4">
    <inertial>
      <origin
        xyz="0.0059454 2.5068E-05 0.051809"
        rpy="0 0 0" />
      <mass
        value="0.5174" />
      <inertia
        ixx="0.00010342"
        ixy="-7.9433E-09"
        ixz="-7.9245E-06"
        iyy="0.0001193"
        iyz="-1.6196E-08"
        izz="8.5637E-05" />
    </inertial>
    <visual>
      <origin
        xyz="0 0 0"
        rpy="0 0 0" />
      <geometry>
        <mesh
          filename="../meshes/arm620/Link4.STL" />
      </geometry>
      <material
        name="">
        <color
          rgba="1 1 1 1" />
      </material>
    </visual>
    <collision>
      <origin
        xyz="0 0 0"
        rpy="0 0 0" />
      <geometry>
        <mesh
          filename= "../meshes/arm620/Link4.STL" />
      </geometry>
    </collision>
  </link>
  <joint
    name="joint4"
    type="revolute">
    <origin
      xyz="0 -0.15558 3.5E-05"
      rpy="1.5708 -1.5708 0" />
    <parent
      link="Link3" />
    <child
      link="Link4" />
    <axis
      xyz="0 0 1" />
    <limit
      lower="-2.967"
      upper="2.967"
      effort="0"
      velocity="0" />
  </joint>
  <link
    name="Link5">
    <inertial>
      <origin
        xyz="0.0095168 0.061153 1.0106E-05"
        rpy="0 0 0" />
      <mass
        value="0.7233" />
      <inertia
        ixx="0.00013586"
        ixy="3.9115E-05"
        ixz="3.3963E-08"
        iyy="0.00010055"
        iyz="-1.3885E-07"
        izz="0.0001594" />
    </inertial>
    <visual>
      <origin
        xyz="0 0 0"
        rpy="0 0 0" />
      <geometry>
        <mesh
          filename= "../meshes/arm620/Link5.STL" />
      </geometry>
      <material
        name="">
        <color
          rgba="1 1 1 1" />
      </material>
    </visual>
    <collision>
      <origin
        xyz="0 0 0"
        rpy="0 0 0" />
      <geometry>
        <mesh
          filename= "../meshes/arm620/Link5.STL" />
      </geometry>
    </collision>
  </link>
  <joint
    name="joint5"
    type="revolute">
    <origin
      xyz="-3.5E-05 1.5362E-05 0.064223"
      rpy="1.5708 0 0" />
    <parent
      link="Link4" />
    <child
      link="Link5" />
    <axis
      xyz="1 0 0" />
    <limit
      lower="-1.5708"
      upper="1.5708"
      effort="0"
      velocity="0" />
  </joint>
  <link
    name="Link6">
    <inertial>
      <origin
        xyz="-0.0023023 0.0016027 0.010682"
        rpy="0 0 0" />
      <mass
        value="0.0953" />
      <inertia
        ixx="1.3179E-05"
        ixy="-9.4826E-08"
        ixz="2.2437E-07"
        iyy="1.3416E-05"
        iyz="-1.8512E-07"
        izz="2.4622E-05" />
    </inertial>
    <visual>
      <origin
        xyz="0 0 0"
        rpy="0 0 0" />
      <geometry>
        <mesh
          filename= "../meshes/arm620/Link6.STL" />
      </geometry>
      <material
        name="">
        <color
          rgba="1 1 1 1" />
      </material>
    </visual>
    <collision>
      <origin
        xyz="0 0 0"
        rpy="0 0 0" />
      <geometry>
        <mesh
          filename= "../meshes/arm620/Link6.STL" />
      </geometry>
    </collision>
  </link>
  <joint
    name="joint6"
    type="revolute">
    <origin
      xyz="-0.00047523 0.095552 0"
      rpy="-1.5709 0 0" />
    <parent
      link="Link5" />
    <child
      link="Link6" />
    <axis
      xyz="0 0 1" />
    <limit
      lower="-2.967"
      upper="2.967"
      effort="0"
      velocity="0" />
  </joint>

  <joint name="link6_robotiq_2f_85_base_joint" type="fixed">
    <origin rpy="0 0 0" xyz="0 0 0"/>
    <parent link="Link6"/>
    <child link="robotiq_2f_85_base"/>
  </joint>

  <link name="robotiq_2f_85_base">
    <inertial>
      <mass value="0.777441"/>
      <origin xyz="0 -2.70394e-05 0.0354675"/>
      <inertia ixx="0.000260285" ixy="0" ixz="0" iyy="0.000225381" iyz="0" izz="0.000152708"/>
    </inertial>
    <visual>
      <geometry>
        <mesh filename="../meshes/robot_iq/robotiq-2f-base.stl" scale="0.1 0.1 0.1"/>
      </geometry>
    </visual>
    <collision>
      <geometry>
        <mesh filename="../meshes/robot_iq/robotiq-2f-base.stl" scale="0.001 0.001 0.001"/>
      </geometry>
    </collision>
  </link>
  <!-- right finger -->
  <joint name="robotiq_2f_85_right_driver_joint" type="revolute">
    <origin rpy="0 0 0" xyz="0 0.0306011 0.054904"/>
    <parent link="robotiq_2f_85_base"/>
    <child link="robotiq_2f_85_right_driver"/>
    <axis xyz="1 0 0"/>
    <limit effort="60" lower="0.0" upper="0.834" velocity="1.91986177778"/>
  </joint>
  <link name="robotiq_2f_85_right_driver">
    <inertial>
      <mass value="0.00899563"/>
      <origin xyz="0 0.0177547 0.00107314"/>
      <inertia ixx="1.72352e-06" ixy="0" ixz="0" iyy="1.60906e-06" iyz="0" izz="3.22006e-07"/>
    </inertial>
    <visual>
      <geometry>
        <mesh filename="../meshes/robot_iq/robotiq-2f-driver.stl" scale="0.1 0.1 0.1"/>
      </geometry>
    </visual>
    <collision>
      <geometry>
        <mesh filename="../meshes/robot_iq/robotiq-2f-driver.stl" scale="0.001 0.001 0.001"/>
      </geometry>
    </collision>
  </link>
  <joint name="robotiq_2f_85_right_coupler_joint" type="fixed">
    <origin rpy="0 0 0" xyz="0 0.0315 -0.0041"/>
    <parent link="robotiq_2f_85_right_driver"/>
    <child link="robotiq_2f_85_right_coupler"/>
  </joint>
  <link name="robotiq_2f_85_right_coupler">
    <inertial>
      <mass value="0.0140974"/>
      <origin xyz="0 0.00301209 0.0232175"/>
      <inertia ixx="4.16206e-06" ixy="0" ixz="0" iyy="3.52216e-06" iyz="0" izz="8.88131e-07"/>
    </inertial>
    <visual>
      <geometry>
        <mesh filename="../meshes/robot_iq/robotiq-2f-coupler.stl" scale="0.1 0.1 0.1"/>
      </geometry>
    </visual>
    <collision>
      <geometry>
        <mesh filename="../meshes/robot_iq/robotiq-2f-coupler.stl" scale="0.001 0.001 0.001"/>
      </geometry>
    </collision>
  </link>
  <joint name="robotiq_2f_85_right_follower_joint" type="revolute">
    <origin rpy="0 0 0" xyz="0 0.0061 0.0471"/>
    <parent link="robotiq_2f_85_right_coupler"/>
    <child link="robotiq_2f_85_right_follower"/>
    <axis xyz="1 0 0"/>
    <limit effort="176" lower="-2.96705911111" upper="2.96705911111" velocity="1.91986177778"/>
    <mimic joint="robotiq_2f_85_right_driver_joint" multiplier="-1"/>
  </joint>
  <link name="robotiq_2f_85_right_follower">
    <inertial>
      <mass value="0.0125222"/>
      <origin xyz="0 -0.011046 0.0124786"/>
      <inertia ixx="2.67415e-06" ixy="0" ixz="0" iyy="2.4559e-06" iyz="0" izz="6.02031e-07"/>
    </inertial>
    <visual>
      <geometry>
        <mesh filename="../meshes/robot_iq/robotiq-2f-follower.stl" scale="0.1 0.1 0.1"/>
      </geometry>  
    </visual>
    <collision>
      <geometry>
        <mesh filename="../meshes/robot_iq/robotiq-2f-follower.stl" scale="0.001 0.001 0.001"/>
      </geometry>
    </collision>
  </link>
  <joint name="robotiq_2f_85_right_pad_joint" type="fixed">
			<parent link="robotiq_2f_85_right_follower"/>
			<child link="robotiq_2f_85_right_pad"/>
	</joint>
	<link name="robotiq_2f_85_right_pad">
		<inertial>
			<mass value="1e-6"/>
			<origin xyz="0.043258 0 0.13"  />
      <inertia ixx="1e-9" iyy="1e-9" izz="1e-9" ixy="0" iyz="0" ixz="0"/>
		</inertial>
		<visual>
			<geometry>
				<mesh filename="../meshes/robot_iq/robotiq-2f-pad.stl" scale="0.0001 0.0001 0.0001"/>
			</geometry>
		</visual>
		<collision>
			<geometry>
				<mesh filename="../meshes/robot_iq/robotiq-2f-pad.stl" scale="0.001 0.001 0.001"/>
			</geometry>
		</collision>
	</link>
  <joint name="robotiq_2f_85_right_spring_link_joint" type="revolute">
    <origin rpy="0 0 0" xyz="0 0.012 0.0614"/>
    <parent link="robotiq_2f_85_base"/>
    <child link="robotiq_2f_85_right_spring_link"/>
    <axis xyz="1 0 0"/>
    <limit effort="176" lower="-2.96705911111" upper="2.96705911111" velocity="1.91986177778"/>
    <mimic joint="robotiq_2f_85_right_driver_joint" multiplier="1"/>
  </joint>
  <link name="robotiq_2f_85_right_spring_link">
    <inertial>
      <mass value="0.0221642"/>
      <origin xyz="0 0.0181624 0.0212658"/>
      <inertia ixx="8.96853e-06" ixy="0" ixz="0" iyy="6.71733e-06" iyz="0" izz="2.63931e-06"/>
    </inertial>
    <visual>
      <geometry>
        <mesh filename="../meshes/robot_iq/robotiq-2f-spring_link.stl" scale="0.1 0.1 0.1"/>
      </geometry>
    </visual>
    <collision>
      <geometry>
        <mesh filename="../meshes/robot_iq/robotiq-2f-spring_link.stl" scale="0.001 0.001 0.001"/>
      </geometry>
    </collision>
  </link>
  <!-- left finger -->
  <joint name="robotiq_2f_85_left_driver_joint" type="revolute">
    <origin rpy="0 0 3.141592653589793" xyz="0 -0.0306011 0.054904"/>
    <parent link="robotiq_2f_85_base"/>
    <child link="robotiq_2f_85_left_driver"/>
    <axis xyz="1 0 0"/>
    <limit effort="176" lower="0.0" upper="0.834" velocity="1.91986177778"/>
    <mimic joint="robotiq_2f_85_right_driver_joint" multiplier="1"/>
  </joint>
  <link name="robotiq_2f_85_left_driver">
    <inertial>
      <mass value="0.00899563"/>
      <origin xyz="0 0.0177547 0.00107314"/>
      <inertia ixx="1.72352e-06" ixy="0" ixz="0" iyy="1.60906e-06" iyz="0" izz="3.22006e-07"/>
    </inertial>
    <visual>
      <geometry>
        <mesh filename="../meshes/robot_iq/robotiq-2f-driver.stl" scale="0.1 0.1 0.1"/>
      </geometry>
    </visual>
    <collision>
      <geometry>
        <mesh filename="../meshes/robot_iq/robotiq-2f-driver.stl" scale="0.001 0.001 0.001"/>
      </geometry>
    </collision>
  </link>
  <joint name="robotiq_2f_85_left_coupler_joint" type="fixed">
    <origin rpy="0 0 0" xyz="0 0.0315 -0.0041"/>
    <parent link="robotiq_2f_85_left_driver"/>
    <child link="robotiq_2f_85_left_coupler"/>
  </joint>
  <link name="robotiq_2f_85_left_coupler">
    <inertial>
      <mass value="0.0140974"/>
      <origin xyz="0 0.00301209 0.0232175"/>
      <inertia ixx="4.16206e-06" ixy="0" ixz="0" iyy="3.52216e-06" iyz="0" izz="8.88131e-07"/>
    </inertial>
    <visual>
      <geometry>
        <mesh filename="../meshes/robot_iq/robotiq-2f-coupler.stl" scale="0.1 0.1 0.1"/>
      </geometry>
    </visual>
    <collision>
      <geometry>
        <mesh filename="../meshes/robot_iq/robotiq-2f-coupler.stl" scale="0.001 0.001 0.001"/>
      </geometry>
    </collision>
  </link>
  <joint name="robotiq_2f_85_left_follower_joint" type="revolute">
    <origin rpy="0 0 0" xyz="0 0.0061 0.0471"/>
    <parent link="robotiq_2f_85_left_coupler"/>
    <child link="robotiq_2f_85_left_follower"/>
    <axis xyz="1 0 0"/>
    <limit effort="176" lower="-2.96705911111" upper="2.96705911111" velocity="1.91986177778"/>
    <mimic joint="robotiq_2f_85_right_driver_joint" multiplier="-1"/>
  </joint>
  <link name="robotiq_2f_85_left_follower">
    <inertial>
      <mass value="0.0125222"/>
      <origin xyz="0 -0.011046 0.0124786"/>
      <inertia ixx="2.67415e-06" ixy="0" ixz="0" iyy="2.4559e-06" iyz="0" izz="6.02031e-07"/>
    </inertial>
    <visual>
      <geometry>
        <mesh filename="../meshes/robot_iq/robotiq-2f-follower.stl" scale="0.1 0.1 0.1"/>
      </geometry>
    </visual>
    <collision>
      <geometry>
        <mesh filename="../meshes/robot_iq/robotiq-2f-follower.stl" scale="0.001 0.001 0.001"/>
      </geometry>
    </collision>
  </link>
  <joint name="robotiq_2f_85_left_pad_joint" type="fixed">
			<parent link="robotiq_2f_85_left_follower"/>
			<child link="robotiq_2f_85_left_pad"/>
		</joint>
		<link name="robotiq_2f_85_left_pad">
			<inertial>
				<mass value="1e-6"/>
				<origin xyz="0.043258 0 0.13"  />
				<inertia ixx="1e-9" iyy="1e-9" izz="1e-9" ixy="0" iyz="0" ixz="0"/>
			</inertial>
      <visual>
        <geometry>
          <mesh name="a" filename="../meshes/robot_iq/robotiq-2f-pad.stl" scale="0.0001 0.0001 0.0001"/>
        </geometry>
      </visual>
			<collision>
				<geometry>
					<mesh name="b" filename="../meshes/robot_iq/robotiq-2f-pad.stl" scale="0.001 0.001 0.001"/>
				</geometry>
			</collision>
		</link>
  <joint name="robotiq_2f_85_left_spring_link_joint" type="revolute">
    <origin rpy="0 0 3.141592653589793" xyz="0 -0.012 0.0614"/>
    <parent link="robotiq_2f_85_base"/>
    <child link="robotiq_2f_85_left_spring_link"/>
    <axis xyz="1 0 0"/>
    <limit effort="176" lower="-2.96705911111" upper="2.96705911111" velocity="1.91986177778"/>
    <mimic joint="robotiq_2f_85_right_driver_joint" multiplier="1"/>
  </joint>
  <link name="robotiq_2f_85_left_spring_link">
    <inertial>
      <mass value="0.0221642"/>
      <origin xyz="0 0.0181624 0.0212658"/>
      <inertia ixx="8.96853e-06" ixy="0" ixz="0" iyy="6.71733e-06" iyz="0" izz="2.63931e-06"/>
    </inertial>
    <visual>
      <geometry>
        <mesh filename="../meshes/robot_iq/robotiq-2f-spring_link.stl" scale="0.1 0.1 0.1"/>
      </geometry>
    </visual>
    <collision>
      <geometry>
        <mesh filename="../meshes/robot_iq/robotiq-2f-spring_link.stl" scale="0.001 0.001 0.001"/>
      </geometry>
    </collision>
  </link>

  <link name="world"/>
  <joint name="base_joint" type="fixed">
      <parent link="world"/>
      <child link="base_link"/>
      <origin xyz="0 0 0" rpy="0 0 0" />
      <axis xyz="0 0 1" />
  </joint>
  
</robot>
