<mujocoinclude>
<!-- =================================================
    Dahuan Gripper Model for MuJoCo
    Converted from URDF gripper description
    Two-finger gripper with slide joints
====================================================== -->

    <body name="dahuan_gripper" pos="0 0 0.02" childclass="dahuangripper">
        <!-- Gripper base link -->
        <inertial pos="-3.9257E-06 -0.00027208 0.0435" mass="1.0"
                  fullinertia="0.00036805 0.0003341 0.00022294 -7.2868E-08 -5.0168E-08 -2.6462E-06" />
        <geom mesh="dahuan-gripper-base" />
        <geom class="dahuan_col" type="mesh" mesh="dahuan-gripper-base"/>

        <!-- Finger 1 (right side) -->
        <body name="dahuan_finger1" pos="0.0132 0.0265 0.093" euler="0 0 -1.5708">
            <inertial pos="0.0030491 -0.0066024 0.0064209" mass="0.014278"
                      fullinertia="1.7567E-06 2.3034E-06 1.3354E-06 -5.7832E-08 2.6803E-08 2.2145E-07" />
            <joint name="dahuan_finger1_joint" range="0 0.025" />
            <geom mesh="dahuan-finger1" />
            <geom class="dahuan_col" type="mesh" mesh="dahuan-finger1" />
            <!-- Collision pad for grasping -->
            <geom class="dahuan_pad_col" type="box" size=".003 .012 .015" pos="0.002 -0.013 0.03"/>
        </body>

        <!-- Finger 2 (left side) -->
        <body name="dahuan_finger2" pos="-0.0132 -0.0265 0.093" euler="0 0 1.5708">
            <inertial pos="0.0030491 -0.0066024 0.0064209" mass="0.014278"
                      fullinertia="1.7567E-06 2.3034E-06 1.3354E-06 -5.7832E-08 2.6803E-08 2.2145E-07" />
            <joint name="dahuan_finger2_joint" range="0 0.025" />
            <geom mesh="dahuan-finger2" />
            <geom class="dahuan_col" type="mesh" mesh="dahuan-finger2" />
            <!-- Collision pad for grasping -->
            <geom class="dahuan_pad_col" type="box" size=".003 .012 .015" pos="0.002 -0.013 0.03"/>
        </body>
    </body>
</mujocoinclude>
